Workbook
Name carton_weight: '[1]LCI parameters'!$C$9
Name cartons_per_pallet: '[1]LCI parameters'!$C$10
Name Cp_fruit: '[1]LCI parameters'!$C$29
Name EC_pre_cooling: '[1]LCI parameters'!$C$30
Name EC_sea_shipment: #REF!
Name fruit_diameter: #REF!
Name fruit_per_carton_number: #REF!
Name fruit_per_carton_weight: '[1]LCI parameters'!$C$7
Name p_lin1: #REF!
Name p_lin2: #REF!
Name pallet_per_container: '[1]LCI parameters'!$C$12
Name precooler_length: '[1]LCI parameters'!$C$32
Name precooler_width: '[1]LCI parameters'!$C$33
Name SECT_shipment: #REF!
Name SECT_storage: #REF!
Name share_fresh: #REF!
Name share_processing: #REF!
Name T_amb_shipment: #REF!
Name T_amb_storage: #REF!
Name Tf_pre_cooling: '[1]LCI parameters'!$C$28
Name Tf_sea_shipment: #REF!
Name Ti_pre_cooling: '[1]LCI parameters'!$C$27
Name time_shipment: #REF!
Name time_storage: #REF!
Name wax_thickness: #REF!

Sheet 1.Goal and scope definition
A1: Goal
A2: To assess the environmental impact of storing fruits and vegetables in a decentralized cold room compared to storing them in natural shade
A4: Scope
A5: Food Storage
A7: Define functional unit (FU):
A8: 1 kg fruits and vegetables stored per day
A11: List for Type of inputs and outputs (a classification system used in LCA to categorize the inputs and outputs of fresh produce during storage):
A13: FromTechnosphere (inputs that are transformed before they enter the system, e.g., energy from solar, battery etc)
A14: ToTechnosphere (outputs that are released into the environment after being transformed by the system)
A16: Indicator
A17: IPCC 2013 global warming potential (GWP100) no LongTerm emissions
A18: carbon footprint (CF) expressed in kg CO2 eq/FU

Sheet 2.Inventory analysis
A1: Scenario: solar-powered cold room | B1: LCA parameters (focus is on Refrigerant, energy and food loss emissions)
B2: Name | C2: Unit | D2: Amount | E2: Description | F2: References
B3: Daily_wattage | C3: kWh/day | D3: 10.65 | E3: Daily energy consumption of 3MT cold room (from CaaS model calculation)
B4: Type_of_thermal_storage | D4: Phase Change Materials | E4: Phase Change Materials (e.g., parrafin wax); Iceblocks Storage; Chilled Water Storage
A5: Solar panel parameters (cold room) | B5: Wax_weight_per_day | C5: kg | D5: 100
B6: Total_Ice_weight_per_day | C6: kg | D6: 100
B7: Cp_water | C7: kJ/kg/K | D7: 4.18
B8: Type_of_battery | D8: Lithium | E8: Lead acid batteries; Lithium ion batteries; Nickel based batteries; Flow batteries
B9: Number_of_battery | D9: 1 | E9: Number of batteries (1 to 10)
B10: Battery_size_per_unit | C10: m3 | D10: 0.01 | E10: Size and number of the battery for powering up the cold room during solar off peak period (m2)
A11: Thermal storage option | B11: Battery_storage_capacity_per_unit | C11: Ah | D11: 100 | E11: Power rating of the batter
B12: Max_charging_current_per_unit | C12: A | D12: 10 | E12: 10-100A
B13: Energy_storage_peak_per_unit | C13: kWh | D13: 15 | E13: Energy storage at peak level (kWh) (range: 1- 50 kWh) or typical battery capacity in kWh
B14: Battery_weight_per_unit | C14: kg | D14: 11.1 | E14: Weight of the battery | F14: https://swissbatt24.ch/versorgungsbatterien/lithium-batterien/2087/acconic-a100d-lifepo4-12v-lithium-versorgungsbatterie-100ah-din?gclid=CjwKCAjw15eqBhBZEiwAbDomEizc-H1IALFzdUapZqSKIZdQDlhiWSjbZFa2566yfS-hQjKcZ3JmBxoC8XQQAvD_BwE)
A15: Battery parameters (cold room)
B16: packaging_type | D16: plastic | E16: Type of crate used in the cold room
B17: Crate_size_length | C17: cm | D17: 1.96 | E17: Length of a crate where fresh produce is stored
B18: Crate_size_width | C18: cm | D18: 1.96 | E18: Width of a crate where fresh produce is stored
B19: Crate_size_height | C19: cm | D19: 1.96 | E19: Height of a crate where fresh produce is stored
B20: Crate_weight | C20: kg | D20: 1.96 | E20: Weight of a crate where fresh produce is stored
B21: no_crate_per_storage | C21: kg | D21: =150*0.25 -> 37.5 | E21: Amount of crate of fruit stored in the cold room (assuming total capacity of 150 crates and a 25% occupancy)
B22: weight_fruit_&_crate | C22: kg | D22: 25 | E22: Weight of fruit stored in a crate
A23: Cold room parameters | B23: fruit_weight | C23: kg | D23: =D22-D20 -> 23.04 | E23: Weight of fruit per basket
B24: Coldroom_insulator | C24: kg | D24: 5 | E24: 2 to 15 kilograms per square meter (for 150 mm reinforced insulation)
B25: Cp_fruit | C25: kJ/kg/K | D25: 3.86 | E25: Average specific heat capacity of the common produce stored in the cold rooms including, Bell pepper, cucmber, apple, onion, and tomato. | F25: https://www.engineeringtoolbox.com/specific-heat-capacity-food-d_295.html
B26: cold room_length | C26: m | D26: 3 | E26: Basal length of the cold room
B27: coldroom_width | C27: m | D27: 2 | E27: Basal width of the cold room
B28: Coldroom_height | C28: m | D28: 3 | E28: Height of the cold room
B29: Cold_room_weight | C29: kg | D29: =D26*D27*D28*66.7 -> 1200.6 | E29: To find the conversion factor from m³ to kg, you need to know the density of the material in question. Density is defined as mass per unit volume. Therefore, the conversion factor is: Density (kg/m³) = Mass (kg) / Volume (m³). So, for this specific material, the conversion factor is approximately 66.67 kg/m³
B30: total_cold_room_weight | C30: kg | D30: =(D21*D22)+D29 -> 2138.1 | E30: Total weight of the cold room (weight of the fruit + packaging (kg))
B31: T_amb_storage | C31: degC | D31: 30 | E31: Ambient temperature during storage: could use a constant value of 30 C or https://power.larc.nasa.gov/data-access-viewer/
B32: Ti_storage | C32: degC | D32: 30 | E32: Initial storage temperature of the cold room = T_amb_storage (from Coldtivate)
B33: Tf_storage_cooldown | C33: degC | D33: 5 | E33: Final cold room temperature to cooldown (from Coldtivate)
B34: T_storage_maintain | C34: degC | D34: 3.5 | E34: Average room temperature during storage
B35: T_room | C35: degC | D35: 8 | E35: Real-time cold room temperature from the app
B36: time_storage | C36: d | D36: 1 | E36: Duration in cold room before checkout (product-specific from Coldtivate)
B37: SECT_storage_cooldown | C37: d | D37: 0.96 | E37: The seven-eighths cooling time (SECT, t7/8) is the time (d) taken for Y = 0.125; where Y = (T_room - Tf_storage_cooldown)/(Ti_storage - Tf_storage_cooldown). We use a default value calcualted from the collected temperature data from coldroom in Ile-Ife (ColdHubs)
B38: EC_fruit | D38: =(D22*D21*1)*D25*(D32-D33)/(D3*3600*1) -> 2.359644 | E38: Energy coefficient, which is the heat that has to be extracted from the produce (in kJ) per kJ of electricity that is consumed. Where EC = fruit_weight per month*Cp_fruit (kJ*(Ti-Tf)/Electricity consumed per month (ecoinvent or cold room)*3600, per 1 kg of fruit
B39: EC_iceblock | D39: =(D6*1)*D7*(D32-0)/(D3*3600*1) -> 0.32707355 | E39: Energy coefficient, which is the heat that has to be extracted from the produce (in kJ) per kJ of electricity that is consumed. Where EC = Total_Ice_weight_per_day*Cp_water (kJ*(Ti_storage-0)/Electricity consumed per month (ecoinvent or cold room)*3600, per 1 kg of fruit
B40: total_heat_removed_fruit | C40: kJ heat removed / 1 kg of fruit | D40: =(D23*D21*D25*(D32-D33))/(D23*D21) -> 96.5 | E40: Total heat removed in the cold room per 1kg of fruit when the fruit is cool down from Ti to set temp (Tf_storage_cooldown. e.g 5degC)
...

Sheet 3.Impact assessment
A1: Step | B1: Name of ecoinvent exchange | C1: Database | D1: Unit | E1: IPCC kg CO2-eq/unit | F1: Impact for active cooling (kg CO2 / kg fruit)
A2: electricity_cooling_fruit | B2: electricity, low voltage//[RoW] electricity production, photovoltaic, 3kWp slanted-roof installation, multi-Si, panel, mounted | C2: EcoInvent v.3.8 | D2: 1 kWh | E2: 0.075684744 | F2: =E2*'2.Inventory analysis'!D43 -> 0.00085977869
A3: electricty_charging_battery | B3: electricity, low voltage//[RoW] electricity production, photovoltaic, 3kWp slanted-roof installation, multi-Si, panel, mounted | C3: EcoInvent v.3.8 | D3: 1 kWh | E3: 0.075684744 | F3: =E3*'2.Inventory analysis'!D44 -> 0.028031387
A4: electricity_iceblock_produced | B4: electricity, low voltage//[RoW] electricity production, photovoltaic, 3kWp slanted-roof installation, multi-Si, panel, mounted | C4: EcoInvent v.3.8 | D4: 1 kWh | E4: 0.075684744 | F4: =E4*'2.Inventory analysis'!D45 -> 0.00093291959
A5: electricity_maintain_cooling | B5: electricity, low voltage//[RoW] electricity production, photovoltaic, 3kWp slanted-roof installation, multi-Si, panel, mounted | C5: EcoInvent v.3.8 | D5: 1 kWh | E5: 0.075684744 | F5: =E5*'2.Inventory analysis'!D47 -> 0.00011568792
A6: refrigerant_cooling | B6: refrigerant R134a//[GLO] market for refrigerant R134a | C6: EcoInvent v.3.8 | D6: kg | E6: 15.12399 | F6: =E6*'2.Inventory analysis'!D50 -> 1.9438918e-09
A7: food_loss_cold_room | B7: biowaste//[RoW] market for biowaste | C7: EcoInvent v.3.8 | D7: kg | E7: 0.21268517 | F7: =E7*'2.Inventory analysis'!D51 -> 0.014887962
A8: share_landfil_operator | B8: biowaste, garden waste//[GLO] market for biowaste, garden waste | C8: EcoInvent v.3.8 | D8: kg | E8: 0.015667136 | F8: =E8*'2.Inventory analysis'!D53 -> 2.1758148e-07
A9: TOTAL IMPACT WITH COLD ROOM | F9: =SUM(F2:F8) -> 0.044827954
A11: food_loss_ambient | B11: biowaste//[RoW] market for biowaste | C11: EcoInvent v.3.8 | D11: kg | E11: 0.21268517 | F11: =E11*'2.Inventory analysis'!D52 -> 0.10634259
A12: TOTAL IMPACT WITHOUT COLD ROOM | F12: =F11 -> 0.10634259
E14: kg CO2/kg of fruit SAVING DUE TO COOLING | F14: =F12-F9 -> 0.061514631
E15: kg CO2 per day SAVING DUE TO COOLING | F15: =F14*'2.Inventory analysis'!D21*'2.Inventory analysis'!D23 -> 53.148641
E16: kg CO2 per year SAVING DUE TO COOLING | F16: =F15*365 -> 19399.254
E17: tonnes CO2 per year SAVING DUE TO COOLING per cold room | F17: =F16/1000 -> 19.399254
E18: tonnes CO2 per year SAVING DUE TO COOLING for 19 cold rooms | F18: =F17*19 -> 368.58582
E19: tonnes CO2 per year SAVING DUE TO COOLING for 500 cold rooms ('full scale') | F19: =F17*500 -> 9699.627

Sheet References
B1: Castellani, V., Fusi, A., & Sala, S. (2017). Consumer Footprint. Basket of Products indicator on Food, EUR 28764 EN, Publications Office of the European Union, Luxembourg, 2017.
B2: Chavan, P., Singh, A. K., & Kaur, G. (2018). Recent progress in the utilization of industrial waste and by‐products of citrus fruits: A review. Journal of Food Process Engineering, 41(8), e12895.
B3: de Cassia Vieira Cardoso, R., Vasconcelos Luckesi, M., Lordelo Guimarães Tavares, P.P., and da Costa Souza, A.L. (2021). Chapter 1 - Fruit and vegetable waste at domiciliary level: what is the panorama? Food Losses, Sustainable Postharvest and Food Technologies (pp. 1-32). Academic Press.
B4: EEA (2013) EMEP/EEA air pollutant emission inventory guidebook 2013 - Technical guidance to prepare national emission inventories. European Environment Agency, Luxembourg, EEA Technical report No 12/2013. Available at http://www.eea.europa.eu.
B5: EC (2021). https://ec.europa.eu/food/system/files/2021-04/fw_lib_stud-rep-pol_ec-know-cen_bioeconomy_2021.pdf)
B6: Fraser, H. (2014). Forced-Air Cooling Systems for Fresh Ontario Fruits and Vegetables. Ontario Ministry of Agriculture, Food and Rural Affairs: Toronto, ON, Canada.
B7: Porat, R., Lichter, A., Terry, L. A., Harker, R., & Buzby, J. (2018). Postharvest losses of fruit and vegetables during retail and in consumers’ homes: Quantifications, causes, and means of prevention. Postharvest biology and technology, 139, 135-149.
B8: Ribal, J., Ramírez-Sanz, C., Estruch, V., Clemente, G., & Sanjuán, N. (2017). Organic versus conventional citrus. Impact assessment and variability analysis in the Comunitat Valenciana (Spain). The International Journal of Life Cycle Assessment, 22, 571-586.
B9: Scholz, K., Eriksson, M., & Strid, I. (2015). Carbon footprint of supermarket food waste. Resources, Conservation and Recycling, 94, 56-65.
B10: Soleil Sitrus, pack-house info: https://www.soleilsitrus.co.za/packhouse/#:~:text=The%20size%20of%20the%20packhouse,small%20amount%20of%20easy%20peelers . Accessed 2022-2023
B11: Stoessel, F., Juraske, R., Pfister, S., & Hellweg, S. (2012). Life cycle inventory and carbon and water foodprint of fruits and vegetables: application to a Swiss retailer. Environmental science & technology, 46(6), 3253-3262.
B12: Van Dooren, C., Janmaat, O., Snoek, J., & Schrijnen, M. (2019). Measuring food waste in Dutch households: A synthesis of three studies. Waste management, 94, 153-164.
... B23: https://swissbatt24.ch/versorgungsbatterien/lithium-batterien/2087/acconic-a100d-lifepo4-12v-lithium-versorgungsbatterie-100ah-din?gclid=CjwKCAjw15eqBhBZEiwAbDomEizc-H1IALFzdUapZqSKIZdQDlhiWSjbZFa2566yfS-hQjKcZ3JmBxoC8XQQAvD_BwE
